<?xml version="1.0" encoding="utf-8"?>
<!-- This URDF was automatically created by SolidWorks to URDF Exporter! Originally created by Stephen Brawner (brawner@gmail.com) 
     Commit Version: 1.6.0-4-g7f85cfe  Build Version: 1.6.7995.38578
     For more information, please see http://wiki.ros.org/sw_urdf_exporter -->
<robot
  name="4.298782525半成品直驱机械臂装配体2">
  <ros2_control name="arm_hw" type="system">
    <hardware>
      <plugin>mujoco_ros2_control/MujocoSystem</plugin>
    </hardware>

    <joint name="joint1">
      <command_interface name="effort"/>
      <state_interface name="position"/>
      <state_interface name="velocity"/>
      <state_interface name="effort"/>
    </joint>

    <joint name="joint2">
      <command_interface name="effort"/>
      <state_interface name="position"/>
      <state_interface name="velocity"/>
      <state_interface name="effort"/>
    </joint>

    <joint name="joint3">
      <command_interface name="effort"/>
      <state_interface name="position"/>
      <state_interface name="velocity"/>
      <state_interface name="effort"/>
    </joint>

    <joint name="joint4">
      <command_interface name="effort"/>
      <state_interface name="position"/>
      <state_interface name="velocity"/>
      <state_interface name="effort"/>
    </joint>

    <joint name="joint5">
      <command_interface name="effort"/>
      <state_interface name="position"/>
      <state_interface name="velocity"/>
      <state_interface name="effort"/>
    </joint>

    <joint name="joint6">
      <command_interface name="effort"/>
      <state_interface name="position"/>
      <state_interface name="velocity"/>
      <state_interface name="effort"/>
    </joint>

  </ros2_control>
  <!-- 虚拟根链接，解决KDL根链接惯量问题 -->
  <link name="world"/>
  <joint name="world_to_base" type="fixed">
    <parent link="world"/>
    <child link="base_link"/>
    <origin xyz="0 0 0" rpy="0 0 0"/>
  </joint>
  <link
    name="base_link">
    <inertial>
      <origin
        xyz="-0.000117046092657544 2.74798811195076E-05 0.0221373814946755"
        rpy="0 0 0" />
      <mass
        value="1.28577081829168" />
      <inertia
        ixx="0.00270428975599141"
        ixy="5.27859401155886E-06"
        ixz="-5.51158906867183E-07"
        iyy="0.00271519433695472"
        iyz="2.22088486078818E-07"
        izz="0.0053501141606494" />
    </inertial>
    <visual>
      <origin
        xyz="0 0 0"
        rpy="0 0 0" />
      <geometry>
        <mesh
          filename="package://arm/model/base_link.STL" />
      </geometry>
      <material
        name="">
        <color
          rgba="0.294117647058824 0.294117647058824 0.294117647058824 1" />
      </material>
    </visual>
    <collision>
      <origin
        xyz="0 0 0"
        rpy="0 0 0" />
      <geometry>
        <mesh
          filename="package://arm/model/base_link.STL" />
      </geometry>
    </collision>
  </link>
  <link
    name="Link1">
    <inertial>
      <origin
        xyz="-4.00115749422947E-05 0.0181639343754783 0.0677222793422555"
        rpy="0 0 0" />
      <mass
        value="2.04146059224224" />
      <inertia
        ixx="0.00318445889213675"
        ixy="-2.70127097153704E-06"
        ixz="1.02605208091895E-05"
        iyy="0.00377726625146936"
        iyz="-1.34031972398601E-05"
        izz="0.00490459111491534" />
    </inertial>
    <visual>
      <origin
        xyz="0 0 0"
        rpy="0 0 0" />
      <geometry>
        <mesh
          filename="package://arm/model/Link1.STL" />
      </geometry>
      <material
        name="">
        <color
          rgba="0.952941176470588 0.925490196078431 0.72156862745098 1" />
      </material>
    </visual>
    <collision>
      <origin
        xyz="0 0 0"
        rpy="0 0 0" />
      <geometry>
        <mesh
          filename="package://arm/model/Link1.STL" />
      </geometry>
    </collision>
  </link>
  <joint
    name="joint1"
    type="revolute">
    <origin
      xyz="0 0 0.05075"
      rpy="0 0 0" />
    <parent
      link="base_link" />
    <child
      link="Link1" />
    <axis
      xyz="0 0 1" />
    <limit
      lower="-1.8"
      upper="1.8"
      effort="50"
      velocity="10" />
  </joint>
  <link
    name="Link2">
    <inertial>
      <origin
        xyz="0.334321979786087 5.18060844616891E-06 -0.0291361434441453"
        rpy="0 0 0" />
      <mass
        value="1.39035437028225" />
      <inertia
        ixx="0.00079665393635923"
        ixy="-2.31945814519378E-06"
        ixz="6.38472746040761E-05"
        iyy="0.0125649781987121"
        iyz="-1.40274406905925E-08"
        izz="0.0130000272821169" />
    </inertial>
    <visual>
      <origin
        xyz="0 0 0"
        rpy="0 0 0" />
      <geometry>
        <mesh
          filename="package://arm/model/Link2.STL" />
      </geometry>
      <material
        name="">
        <color
          rgba="0.898039215686275 0.917647058823529 0.929411764705882 1" />
      </material>
    </visual>
    <collision>
      <origin
        xyz="0 0 0"
        rpy="0 0 0" />
      <geometry>
        <mesh
          filename="package://arm/model/Link2.STL" />
      </geometry>
    </collision>
  </link>
  <joint
    name="joint2"
    type="revolute">
    <origin
      xyz="0 0.0278300000000136 0.12375000000003"
      rpy="-1.5707963267949 -1.57 0" />
    <parent
      link="Link1" />
    <child
      link="Link2" />
    <axis
      xyz="0 0 1" />
    <limit
      lower="-1.570796327"
      upper="1.570796327"
      effort="50"
      velocity="10" />
  </joint>
  <link
    name="Link3">
    <inertial>
      <origin
        xyz="0.375917949539704 0.000538460021310749 0.0289038156960655"
        rpy="0 0 0" />
      <mass
        value="0.785255181937118" />
      <inertia
        ixx="0.000303243267147682"
        ixy="3.53969258527653E-06"
        ixz="3.97969891287926E-06"
        iyy="0.00513699339153058"
        iyz="-1.81694471616894E-06"
        izz="0.00537904099407911" />
    </inertial>
    <visual>
      <origin
        xyz="0 0 0"
        rpy="0 0 0" />
      <geometry>
        <mesh
          filename="package://arm/model/Link3.STL" />
      </geometry>
      <material
        name="">
        <color
          rgba="0.898039215686275 0.917647058823529 0.929411764705882 1" />
      </material>
    </visual>
    <collision>
      <origin
        xyz="0 0 0"
        rpy="0 0 0" />
      <geometry>
        <mesh
          filename="package://arm/model/Link3.STL" />
      </geometry>
    </collision>
  </link>
  <joint
    name="joint3"
    type="revolute">
    <origin
      xyz="0.500000000000005 0 -0.0455028735632288"
      rpy="3.14159265358979 0 0" />
    <parent
      link="Link2" />
    <child
      link="Link3" />
    <axis
      xyz="0 0 1" />
    <limit
      lower="-2.9"
      upper="2.9"
      effort="50"
      velocity="10" />
  </joint>
  <link
    name="Link4">
    <inertial>
      <origin
        xyz="0.0684316268079724 0.0374069895176231 0.0241013920633018"
        rpy="0 0 0" />
      <mass
        value="0.372073709541278" />
      <inertia
        ixx="0.000176970269471728"
        ixy="-5.03511839917621E-06"
        ixz="-2.99014130120356E-08"
        iyy="0.000198806883964514"
        iyz="-2.82905520405028E-08"
        izz="0.000214560508306232" />
    </inertial>
    <visual>
      <origin
        xyz="0 0 0"
        rpy="0 0 0" />
      <geometry>
        <mesh
          filename="package://arm/model/Link4.STL" />
      </geometry>
      <material
        name="">
        <color
          rgba="0.294117647058824 0.294117647058824 0.294117647058824 1" />
      </material>
    </visual>
    <collision>
      <origin
        xyz="0 0 0"
        rpy="0 0 0" />
      <geometry>
        <mesh
          filename="package://arm/model/Link4.STL" />
      </geometry>
    </collision>
  </link>
  <joint
    name="joint4"
    type="revolute">
    <origin
      xyz="0.509639999999998 0 0.0110471264367704"
      rpy="0 0 0" />
    <parent
      link="Link3" />
    <child
      link="Link4" />
    <axis
      xyz="0 0 1" />
    <limit
      lower="-2.0"
      upper="1.8"
      effort="50"
      velocity="10" />
  </joint>
  <link
    name="Link5">
    <inertial>
      <origin
        xyz="0.0396747010785532 0.015724993769755 0.0422073707036243"
        rpy="0 0 0" />
      <mass
        value="0.112220070755106" />
      <inertia
        ixx="2.37673896282578E-05"
        ixy="-1.2990085245332E-06"
        ixz="7.61111941685778E-09"
        iyy="2.65325508636835E-05"
        iyz="-1.92087226294267E-08"
        izz="3.31518808847527E-05" />
    </inertial>
    <visual>
      <origin
        xyz="0 0 0"
        rpy="0 0 0" />
      <geometry>
        <mesh
          filename="package://arm/model/Link5.STL" />
      </geometry>
      <material
        name="">
        <color
          rgba="0.294117647058824 0.294117647058824 0.294117647058824 1" />
      </material>
    </visual>
    <collision>
      <origin
        xyz="0 0 0"
        rpy="0 0 0" />
      <geometry>
        <mesh
          filename="package://arm/model/Link5.STL" />
      </geometry>
    </collision>
  </link>
  <joint
    name="joint5"
    type="revolute">
    <origin
      xyz="0.0760000000000024 0.043999999999999 0.0245500000000014"
      rpy="1.57 0.37 0" />
    <parent
      link="Link4" />
    <child
      link="Link5" />
    <axis
      xyz="0 0 1" />
    <limit
      lower="-0.0349"
      upper="0.0349"
      effort="50"
      velocity="10" />
  </joint>
  <link
    name="Link6">
    <inertial>
      <origin
        xyz="-4.44089209850063E-16 0 0.0245509014980994"
        rpy="0 0 0" />
      <mass
        value="0.150213928644987" />
      <inertia
        ixx="7.59512548879525E-05"
        ixy="2.03287907341032E-20"
        ixz="2.37169225231204E-20"
        iyy="7.59512548879525E-05"
        iyz="1.10114283143059E-20"
        izz="0.000112386901497531" />
    </inertial>
    <visual>
      <origin
        xyz="0 0 0"
        rpy="0 0 0" />
      <geometry>
        <mesh
          filename="package://arm/model/Link6.STL" />
      </geometry>
      <material
        name="">
        <color
          rgba="0.113725490196078 0.113725490196078 0.113725490196078 1" />
      </material>
    </visual>
    <collision>
      <origin
        xyz="0 0 0"
        rpy="0 0 0" />
      <geometry>
        <mesh
          filename="package://arm/model/Link6.STL" />
      </geometry>
    </collision>
  </link>
  <joint
    name="joint6"
    type="revolute">
    <origin
      xyz="0.0629861815027267 0.024956030127103 0.0467500000000002"
      rpy="1.5707963267949 -0.25158845704293 1.94803497441332" />
    <parent
      link="Link5" />
    <child
      link="Link6" />
    <axis
      xyz="0 0 1" />
    <limit
      lower="-3.14159"
      upper="3.14159"
      effort="50"
      velocity="10" />
  </joint>
</robot>
