<mujoco model="robotic_arm">
  <compiler angle="radian" />
  <asset>
    <mesh name="base_link" file="base_link.STL" />
    <mesh name="Link1" file="Link1.STL" />
    <mesh name="Link2" file="Link2.STL" />
    <mesh name="Link3" file="Link3.STL" />
    <mesh name="Link4" file="Link4.STL" />
    <mesh name="Link5" file="Link5.STL" />
    <mesh name="Link6" file="Link6.STL" />
  </asset>
  <worldbody>
    <body name="base_link">
      <geom type="mesh" rgba="0.294118 0.294118 0.294118 1" mesh="base_link" />
      <site name="tool_site" pos="0 0 0" size="0.01" />
      <body name="Link1" pos="0 0 0.05075">
        <inertial pos="-4.00116e-05 0.0181639 0.0677223" quat="-0.00576303 0.709195 -0.00266122 0.704983" mass="2.04146" diaginertia="0.00490481 0.00377712 0.00318439" />
        <joint name="joint1" pos="0 0 0" axis="0 0 1" range="-1.8 1.8" actuatorfrcrange="-50 50" />
        <geom type="mesh" rgba="0.952941 0.92549 0.721569 1" mesh="Link1" />
        <body name="Link2" pos="0 0.02783 0.12375" quat="0.500199 -0.500199 -0.499801 -0.499801">
          <inertial pos="0.334322 5.18061e-06 -0.0291361" quat="-9.10492e-05 0.708954 4.8195e-05 0.705255" mass="1.39035" diaginertia="0.0130004 0.012565 0.000796319" />
          <joint name="joint2" pos="0 0 0" axis="0 0 1" range="-1.5708 1.5708" actuatorfrcrange="-50 50" />
          <geom type="mesh" rgba="0.898039 0.917647 0.929412 1" mesh="Link2" />
          <body name="Link3" pos="0.5 0 -0.0455029" quat="0 1 0 0">
            <inertial pos="0.375918 0.00053846 0.0289038" quat="-0.00238956 0.707378 -0.00290965 0.706825" mass="0.785255" diaginertia="0.00537906 0.00513698 0.000303238" />
            <joint name="joint3" pos="0 0 0" axis="0 0 1" range="-2.9 2.9" actuatorfrcrange="-50 50" />
            <geom type="mesh" rgba="0.898039 0.917647 0.929412 1" mesh="Link3" />
            <body name="Link4" pos="0.50964 0 0.0110471">
              <camera name="overview" pos="0.1 0.09 -0.03" xyaxes="0 0 1 0 1 0" />
              <inertial pos="0.0684316 0.037407 0.0241014" quat="-0.0767806 0.70272 0.0756926 0.70325" mass="0.372074" diaginertia="0.000214561 0.000199912 0.000175865" />
              <joint name="joint4" pos="0 0 0" axis="0 0 1" range="-2 1.8" actuatorfrcrange="-50 50" />
              <geom type="mesh" rgba="0.294118 0.294118 0.294118 1" mesh="Link4" />
              <body name="Link5" pos="0.076 0.044 0.02455" quat="0.695318 0.694764 0.130122 -0.130018">
                <inertial pos="0.0396747 0.015725 0.0422074" quat="-0.133719 0.694797 0.131368 0.694348" mass="0.11222" diaginertia="3.3152e-05 2.7047e-05 2.32529e-05" />
                <joint name="joint5" pos="0 0 0" axis="0 0 1" range="-0.0349 0.0349" actuatorfrcrange="-50 50" />
                <geom type="mesh" rgba="0.294118 0.294118 0.294118 1" mesh="Link5" />
                <body name="Link6" pos="0.0629862 0.024956 0.04675" quat="0.32086 0.467622 0.530405 0.630118">
                  <inertial pos="0 0 0.0245509" quat="0.5 0.5 -0.5 0.5" mass="0.150214" diaginertia="0.000112387 7.59513e-05 7.59513e-05" />
                  <joint name="joint6" pos="0 0 0" axis="0 0 1" range="-3.14159 3.14159" actuatorfrcrange="-50 50" />
                  <geom type="mesh" rgba="0.113725 0.113725 0.113725 1" mesh="Link6" />
                  <site name="ee_site" pos="0 0 0.02" size="0.01" />
                </body>
              </body>
            </body>
          </body>
        </body>
      </body>
    </body>
  </worldbody>
  <contact>
    <exclude body1="base_link" body2="Link1" />
    <exclude body1="Link1" body2="Link2" />
    <exclude body1="Link2" body2="Link3" />
    <exclude body1="Link3" body2="Link4" />
    <exclude body1="Link4" body2="Link5" />
    <exclude body1="Link5" body2="Link6" />
  </contact>
  <actuator>
    <motor name="motor1" joint="joint1" gear="1" ctrllimited="true" ctrlrange="-20 20" />
    <motor name="motor2" joint="joint2" gear="1" ctrllimited="true" ctrlrange="-60 60" />
    <motor name="motor3" joint="joint3" gear="1" ctrllimited="true" ctrlrange="-60 60" />
    <motor name="motor4" joint="joint4" gear="1" ctrllimited="true" ctrlrange="-20 20" />
    <motor name="motor5" joint="joint5" gear="1" ctrllimited="true" ctrlrange="-8 8" />
    <motor name="motor6" joint="joint6" gear="1" ctrllimited="true" ctrlrange="-8 8" />
  </actuator>
  <sensor>
    <actuatorpos name="motor1_p" actuator="motor1" />
    <actuatorpos name="motor2_p" actuator="motor2" />
    <actuatorpos name="motor3_p" actuator="motor3" />
    <actuatorpos name="motor4_p" actuator="motor4" />
    <actuatorpos name="motor5_p" actuator="motor5" />
    <actuatorpos name="motor6_p" actuator="motor6" />
    <actuatorvel name="motor1_v" actuator="motor1" />
    <actuatorvel name="motor2_v" actuator="motor2" />
    <actuatorvel name="motor3_v" actuator="motor3" />
    <actuatorvel name="motor4_v" actuator="motor4" />
    <actuatorvel name="motor5_v" actuator="motor5" />
    <actuatorvel name="motor6_v" actuator="motor6" />
    <actuatorfrc name="motor1_f" actuator="motor1" noise="1e-3" />
    <actuatorfrc name="motor2_f" actuator="motor2" noise="1e-3" />
    <actuatorfrc name="motor3_f" actuator="motor3" noise="1e-3" />
    <actuatorfrc name="motor4_f" actuator="motor4" noise="1e-3" />
    <actuatorfrc name="motor5_f" actuator="motor5" noise="1e-3" />
    <actuatorfrc name="motor6_f" actuator="motor6" noise="1e-3" />
    <framepos name="ee_pos" objtype="site" objname="ee_site" />
    <framequat name="ee_quat" objtype="site" objname="ee_site" />
  </sensor>
</mujoco>